Traceback (most recent call last):
  File "/home/javitrucas/miniconda3/envs/tfg/lib/python3.11/site-packages/wandb/sdk/wandb_config.py", line 165, in __getattr__
    return self.__getitem__(key)
           ^^^^^^^^^^^^^^^^^^^^^
  File "/home/javitrucas/miniconda3/envs/tfg/lib/python3.11/site-packages/wandb/sdk/wandb_config.py", line 130, in __getitem__
    return self._items[key]
           ~~~~~~~~~~~^^^^^
KeyError: 'val_prop'

The above exception was the direct cause of the following exception:

Traceback (most recent call last):
  File "/home/javitrucas/TFG/scripts/medical_scripts/medical_main.py", line 43, in <module>
    train_dataset, val_dataset = load_dataset(config=config, mode="train_val")
                                 ^^^^^^^^^^^^^^^^^^^^^^^^^^^^^^^^^^^^^^^^^^^^^
  File "/home/javitrucas/TFG/scripts/medical_scripts/../../scripts/dataset_loader.py", line 14, in load_dataset
    val_prop = config.val_prop
               ^^^^^^^^^^^^^^^
  File "/home/javitrucas/miniconda3/envs/tfg/lib/python3.11/site-packages/wandb/sdk/wandb_config.py", line 167, in __getattr__
    raise AttributeError(
AttributeError: <class 'wandb.sdk.wandb_config.Config'> object has no attribute 'val_prop'
